# JavaScript 错误处理

## 问答题

### 1.什么是错误处理？为什么要错误处理？

- JS代码执行时，可能会遇到各种错误，这时候JS引擎默认情况下会停止，并抛出一个错误，而我们可以try...catch...finally来处理那些可以预知到，或者可能发生的错误。
- 错误处理可以让JS代码在运行出错后仍然可以继续往下运行，给客户或者开发人员提供产生错误的提示或信息，回收错误代码占用的资源等，总而言之，错误处理能增加程序的鲁棒性。

### 2.常见的错误有哪些？

- EvalError(eval错误)
- RangeError(范围错误)
- ReferenceError(引用错误)
- SyntaxError(语法错误)
- TypeError(类型错误)
- URIError(URI错误)

### 3.能用 if 语句替代错误处理吗？如果能，请给出实例代码，如果不能，请说明原因（开放题）

- 不能，使用if语句处理错误，前提是产生错误的代码会返回一个与false等价的结果，有些错误比如范围错误，类型错误等，可以用if判断来替代错误处理产生相同的效果，但是其他很多类型的错误，并不能单纯用if来实现它们的错误处理。

### 4.如何抛出一个错误？

- 使用throw关键字可以抛出任何类型的对象，一般使用Error来构建抛出的对象。
  
```bash
try{
  throw new Error("a error with more info")
}catch(err){
  console.log(err)
}
```

### 5.以下代码可以捕获异常吗？为什么？

```bash
function a(){
 throw new Error("An error")
}
function b(){
 a();
}
try{
 b()
}catch(err){
 console.log(err)
}
```

- 可以，程序的调用是递归式的，只要是在try代码块里，不管是被直接调用，还是被间接调用，一旦抛出异常，这个异常会被向上传播，catch一定能捕捉到这个异常。

### 6.finally 子句有什么用？

- finally子句里定义了try和catch之后一定会执行的代码，finally子句里的代码是能保证执行的，无论之前try语句块里代码是否抛出了错误。

### 7.JavaScript 中 throw 可以抛出非 Error 类型的异常吗？请动手试试

- 可以，throw能抛出任意类型的对象，或者是Error的各种子类。
  
```bash
try{
   throw 1;
}  
catch(e){
    console.log(e);// 1
}
try{
   throw [1,2,3];
}  
catch(e){
    console.log(e);//(3)[1,2,3]
}
try{
   throw new TypeError("this is typeError!");
}  
catch(e){
    console.log(e);
    /*TypeError: this is typeError!
    at index.html:24*/
}
```

### 8.try catch 语句可以嵌套吗？ 如何嵌套？

- 可以嵌套
- 在try语句块和catch语句块里都可以加上另一对try catch。嵌套时，同层级的catch捕捉同层级的try抛出的异常，同时应注意throw后的语句不会被执行，所以不能再throw后嵌套一对新的try catch。
下面代码输出1,3；

    ```bash
    try{
    throw "1";
    try{
        throw "2";
    }
    catch(e){
        console.log(e);
    }

    }
    catch(e){
    console.log(e);
    try{
        throw "3";
    }
    catch(e){
        console.log(e);
    }
    }
    ```

## 代码题

### 1.请构造一段会产生异常的代码（注意：不是一定会产生，是有一定概率产生异常），然后使用异常处理机制处理它

[代码](https://github.com/LeoneKuma/mfs-homework/blob/master/Base_JS_32/index.html)  
[预览](http://47.100.99.130:8080/mfs-homework/web/Base_JS_32/index.html)

### 2.以下代码能不能正常捕获异常，如果不能请分析原因并修改代码使其可以正常捕获异常

```bash
function asyncTask(){
 setTimeout(function(){
   throw new Error("An error")
 },1000)
}
try{
 asyncTask()
} catch(err){
 console.log(err)
}
```

- 不能捕捉到错误，只会报错。
- 原因是JavaScript不能捕捉到异步错误。
  可以将try catch写进异步代码里来捕捉异步错误。

```bash
setTimeout(function(){
function asyncTask(){
    throw new Error("An error");
}
try{
 asyncTask()
} catch(err){
 console.log(err)
}
},1000)
```
